Workbook

Sheet Monthly Flex
B2: Hours | C2: Monthly Cost
B3: Monthly | C3: 3 Months | D3: 6 Months | E3: 12 Months | F3: 24 Months
B4: 10 | C4: =I40 -> 1500 | D4: =J40 -> 1500 | E4: =K40 -> 1440 | F4: =L40 -> 1400
C5: =C40 -> 0 | D5: =D40 -> 0 | E5: =E40 -> 0.06 | F5: =F40 -> 0.1
B6: 15 | C6: =I41 -> 2250 | D6: =J41 -> 2205 | E6: =K41 -> 2130 | F6: =L41 -> 2085
C7: =C41 -> 0 | D7: =D41 -> 0.03 | E7: =E41 -> 0.08 | F7: =F41 -> 0.11
B8: 20 | C8: =I42 -> 3000 | D8: =J42 -> 2920 | E8: =K42 -> 2800 | F8: =L42 -> 2760
C9: =C42 -> 0 | D9: =D42 -> 0.04 | E9: =E42 -> 0.1 | F9: =F42 -> 0.12
B10: 25 | C10: =I43 -> 3750 | D10: =J43 -> 3625 | E10: =K43 -> 3450 | F10: =L43 -> 3400
C11: =C43 -> 0 | D11: =D43 -> 0.05 | E11: =E43 -> 0.12 | F11: =F43 -> 0.14
B12: 30 | C12: =I44 -> 4380 | D12: =J44 -> 4320 | E12: =K44 -> 4080 | F12: =L44 -> 4020
C13: =C44 -> 0.04 | D13: =D44 -> 0.06 | E13: =E44 -> 0.14 | F13: =F44 -> 0.16
B14: 40 | C14: =I45 -> 5760 | D14: =J45 -> 5680 | E14: =K45 -> 5360 | F14: =L45 -> 5280
C15: =C45 -> 0.06 | D15: =D45 -> 0.08 | E15: =E45 -> 0.16 | F15: =F45 -> 0.18
B16: 50 | C16: =I46 -> 7100 | D16: =J46 -> 7000 | E16: =K46 -> 6500 | F16: =L46 -> 6400
C17: =C46 -> 0.08 | D17: =D46 -> 0.1 | E17: =E46 -> 0.2 | F17: =F46 -> 0.22
B18: 60 | C18: =I47 -> 8400 | D18: =J47 -> 8280 | E18: =K47 -> 7800 | F18: =L47 -> 7680
C19: =C47 -> 0.1 | D19: =D47 -> 0.12 | E19: =E47 -> 0.2 | F19: =F47 -> 0.22
B20: 80 | C20: =I48 -> 11200 | D20: =J48 -> 11040 | E20: =K48 -> 10400 | F20: =L48 -> 10240
C21: =C48 -> 0.1 | D21: =D48 -> 0.12 | E21: =E48 -> 0.2 | F21: =F48 -> 0.22
B22: 100 | C22: =I49 -> 14000 | D22: =J49 -> 13600 | E22: =K49 -> 13000 | F22: =L49 -> 12800
C23: =C49 -> 0.1 | D23: =D49 -> 0.14 | E23: =E49 -> 0.2 | F23: =F49 -> 0.22
B24: 120 | C24: =I50 -> 16800 | D24: =J50 -> 16320 | E24: =K50 -> 15600 | F24: =L50 -> 15360
C25: =C50 -> 0.1 | D25: =D50 -> 0.14 | E25: =E50 -> 0.2 | F25: =F50 -> 0.22
B26: 140 | C26: =I51 -> 19600 | D26: =J51 -> 19040 | E26: =K51 -> 18200 | F26: =L51 -> 17920
C27: =C51 -> 0.1 | D27: =D51 -> 0.14 | E27: =E51 -> 0.2 | F27: =F51 -> 0.22
B28: 160 | C28: =I52 -> 22400 | D28: =J52 -> 21760 | E28: =K52 -> 20800 | F28: =L52 -> 20480
C29: =C52 -> 0.1 | D29: =D52 -> 0.14 | E29: =E52 -> 0.2 | F29: =F52 -> 0.22
B30: 180 | C30: =I53 -> 25200 | D30: =J53 -> 24480 | E30: =K53 -> 23400 | F30: =L53 -> 23040
C31: =C53 -> 0.1 | D31: =D53 -> 0.14 | E31: =E53 -> 0.2 | F31: =F53 -> 0.22
B32: 200 | C32: =I54 -> 28000 | D32: =J54 -> 27200 | E32: =K54 -> 26000 | F32: =L54 -> 25600
D33: =D54 -> 0.14 | E33: =E54 -> 0.2 | F33: =F54 -> 0.22
B37: Monthly Recurring Services (Flex Hour Retainer)
B38: % Discount | C38: 3 mo. | D38: 6 mo. | E38: 12 mo. | F38: 24 mo. | H38: Hours | I38: Monthly Cost
B39: Monthly Hours | C39: 1 | D39: 2 | E39: 3 | F39: 4 | H39: Monthly Hours | I39: 3 Months | J39: 6 Months | K39: 12 Months | L39: 24 Months
B40: 10 | C40: 0 | D40: 0 | E40: 0.06 | F40: 0.1 | H40: 10 | I40: =$H40*(150-(100*C40)) -> 1500 | J40: =$H40*(150-(100*D40)) -> 1500 | K40: =$H40*(150-(100*E40)) -> 1440 | L40: =$H40*(150-(100*F40)) -> 1400
B41: 15 | C41: 0 | D41: 0.03 | E41: 0.08 | F41: 0.11 | H41: 15 | I41: =$H41*(150-(100*C41)) -> 2250 | J41: =$H41*(150-(100*D41)) -> 2205 | K41: =$H41*(150-(100*E41)) -> 2130 | L41: =$H41*(150-(100*F41)) -> 2085
B42: 20 | C42: 0 | D42: 0.04 | E42: 0.1 | F42: 0.12 | H42: 20 | I42: =$H42*(150-(100*C42)) -> 3000 | J42: =$H42*(150-(100*D42)) -> 2920 | K42: =$H42*(150-(100*E42)) -> 2800 | L42: =$H42*(150-(100*F42)) -> 2760
B43: 25 | C43: 0 | D43: 0.05 | E43: 0.12 | F43: 0.14 | H43: 25 | I43: =$H43*(150-(100*C43)) -> 3750 | J43: =$H43*(150-(100*D43)) -> 3625 | K43: =$H43*(150-(100*E43)) -> 3450 | L43: =$H43*(150-(100*F43)) -> 3400
B44: 30 | C44: 0.04 | D44: 0.06 | E44: 0.14 | F44: 0.16 | H44: 30 | I44: =$H44*(150-(100*C44)) -> 4380 | J44: =$H44*(150-(100*D44)) -> 4320 | K44: =$H44*(150-(100*E44)) -> 4080 | L44: =$H44*(150-(100*F44)) -> 4020
...

Sheet Project
B2: Projects
B3: Hours | D3: Cost
B4: Monthly Hours | C4: Total Project Hours (spread across 6 Months) | D4: Monthly Cost | E4: Total Cost (Monthly Cost x 6 Months)
B5: 10 | C5: 60 | D5: =B5*(150-(100*D6)) -> 1500 | E5: =D5*6 -> 9000
D6: ='Monthly Flex'!D40 -> 0
B7: 12.5 | C7: 75 | D7: =B7*(150-(100*D8)) -> 1875 | E7: =D7*6 -> 11250
D8: ='Monthly Flex'!D40 -> 0
B9: 15 | C9: 90 | D9: =B9*(150-(100*D10)) -> 2205 | E9: =D9*6 -> 13230
D10: ='Monthly Flex'!D41 -> 0.03
B11: 17.5 | C11: 105 | D11: =B11*(150-(100*D12)) -> 2572.5 | E11: =D11*6 -> 15435
D12: ='Monthly Flex'!D41 -> 0.03
B13: 20 | C13: 120 | D13: =B13*(150-(100*D14)) -> 2920 | E13: =D13*6 -> 17520
D14: ='Monthly Flex'!D42 -> 0.04
B15: 22.5 | C15: 135 | D15: =B15*(150-(100*D16)) -> 3285 | E15: =D15*6 -> 19710
D16: ='Monthly Flex'!D42 -> 0.04
B17: 25 | C17: 150 | D17: =B17*(150-(100*D18)) -> 3625 | E17: =D17*6 -> 21750
D18: ='Monthly Flex'!D43 -> 0.05
B19: 27.5 | C19: 165 | D19: =B19*(150-(100*D20)) -> 3987.5 | E19: =D19*6 -> 23925
D20: ='Monthly Flex'!D43 -> 0.05
B21: 30 | C21: 180 | D21: =B21*(150-(100*D22)) -> 4320 | E21: =D21*6 -> 25920
D22: ='Monthly Flex'!D44 -> 0.06
B23: 35 | C23: 210 | D23: =B23*(150-(100*D24)) -> 5040 | E23: =D23*6 -> 30240
D24: ='Monthly Flex'!D44 -> 0.06
B25: 40 | C25: 240 | D25: =B25*(150-(100*D26)) -> 5680 | E25: =D25*6 -> 34080
D26: ='Monthly Flex'!D45 -> 0.08
B27: 45 | C27: 270 | D27: =B27*(150-(100*D28)) -> 6390 | E27: =D27*6 -> 38340
D28: ='Monthly Flex'!D45 -> 0.08
B29: 50 | C29: 300 | D29: =B29*(150-(100*D30)) -> 7000 | E29: =D29*6 -> 42000
D30: ='Monthly Flex'!D46 -> 0.1
B31: 55 | C31: 330 | D31: =B31*(150-(100*D32)) -> 7700 | E31: =D31*6 -> 46200
D32: ='Monthly Flex'!D46 -> 0.1
B33: 60 | C33: 360 | D33: =B33*(150-(100*D34)) -> 8280 | E33: =D33*6 -> 49680
D34: ='Monthly Flex'!D47 -> 0.12
B35: 70 | C35: 420 | D35: =B35*(150-(100*D36)) -> 9660 | E35: =D35*6 -> 57960
D36: ='Monthly Flex'!D47 -> 0.12
B37: 80 | C37: 480 | D37: =B37*(150-(100*D38)) -> 11040 | E37: =D37*6 -> 66240
D38: ='Monthly Flex'!D48 -> 0.12
B39: 90 | C39: 540 | D39: =B39*(150-(100*D40)) -> 12420 | E39: =D39*6 -> 74520
D40: ='Monthly Flex'!D48 -> 0.12
B41: 100 | C41: 600 | D41: =B41*(150-(100*D42)) -> 13600 | E41: =D41*6 -> 81600
...

Sheet Other

Sheet Clients w MSAs
A1: Client Code | B1: Client | C1: Expiration Date | D1: Link to PandaDoc Template | E1: Link to MSA
B2: Ormco
B3: Canon
B4: Mississippi State
B5: Edwards
